Workbook

Sheet Summary
A1: NEXORA – Measure Dictionary Summary
A2: Counts recalculate from the Measures sheet.
A4: Total measures | B4: =COUNTA(Measures!$D$5:$D$214) -> 210
A5: Measures with a reference value | B5: =COUNT(Measures!$K$5:$K$214) -> 46
A7: Folder | B7: Measures | D7: Data type | E7: Measures
A8: 00 Utilities | B8: =COUNTIF(Measures!$B$5:$B$214,A8) -> 5 | D8: Currency | E8: =COUNTIF(Measures!$H$5:$H$214,D8) -> 43
A9: 01 Sales & Profit | B9: =COUNTIF(Measures!$B$5:$B$214,A9) -> 32 | D9: Whole number | E9: =COUNTIF(Measures!$H$5:$H$214,D9) -> 42
A10: 02 Time Intelligence | B10: =COUNTIF(Measures!$B$5:$B$214,A10) -> 26 | D10: Decimal | E10: =COUNTIF(Measures!$H$5:$H$214,D10) -> 11
A11: 03 KPI Cards | B11: =COUNTIF(Measures!$B$5:$B$214,A11) -> 15 | D11: Percentage | E11: =COUNTIF(Measures!$H$5:$H$214,D11) -> 60
A12: 04 Products & Brands | B12: =COUNTIF(Measures!$B$5:$B$214,A12) -> 33 | D12: Ratio | E12: =COUNTIF(Measures!$H$5:$H$214,D12) -> 1
A13: 05 Customers | B13: =COUNTIF(Measures!$B$5:$B$214,A13) -> 25 | D13: Date | E13: =COUNTIF(Measures!$H$5:$H$214,D13) -> 2
A14: 06 Marketing & Channels | B14: =COUNTIF(Measures!$B$5:$B$214,A14) -> 12 | D14: Text | E14: =COUNTIF(Measures!$H$5:$H$214,D14) -> 38
A15: 07 Operations | B15: =COUNTIF(Measures!$B$5:$B$214,A15) -> 15 | D15: Color (hex) | E15: =COUNTIF(Measures!$H$5:$H$214,D15) -> 13
A16: 08 Customer Experience | B16: =COUNTIF(Measures!$B$5:$B$214,A16) -> 10 | D16: Total | E16: =SUM(E8:E15) -> 210
A17: 09 Insights & Titles | B17: =COUNTIF(Measures!$B$5:$B$214,A17) -> 27
A18: 10 Data Quality | B18: =COUNTIF(Measures!$B$5:$B$214,A18) -> 10
A19: Total | B19: =SUM(B8:B18) -> 210
A20: Check (should equal Total measures) | B20: =IF(B19=B4,"OK","MISMATCH") -> OK
A22: Delivered TMDL scripts
A23: Script file | B23: Measures
A24: NEXORA_Customers_Page_Addon.tmdl.txt | B24: =COUNTIF(Measures!$L$5:$L$214,A24) -> 5
A25: NEXORA_Decision_Page_Addon.tmdl.txt | B25: =COUNTIF(Measures!$L$5:$L$214,A25) -> 17
A26: NEXORA_Measures_Core.tmdl.txt | B26: =COUNTIF(Measures!$L$5:$L$214,A26) -> 170
A27: NEXORA_Product_Performance.tmdl.txt | B27: =COUNTIF(Measures!$L$5:$L$214,A27) -> 2
A28: NEXORA_Products_Page_Addon.tmdl.txt | B28: =COUNTIF(Measures!$L$5:$L$214,A28) -> 15
A29: chat (single measure) | B29: =COUNTIF(Measures!$L$5:$L$214,A29) -> 1
A31: How to use: open the Measures sheet, filter by Folder or search a measure name; the DAX formula column can be copied as-is.
A32: Measures you created yourself in Power BI (for example the KPI visuals' own deltas) are not part of this list.
A33: Folder names match the Display folders in Power BI's Data pane, so the dictionary mirrors the model.

Sheet Measures
A1: NEXORA – DAX Measure Dictionary
A2: Every measure delivered in the TMDL scripts, grouped by display folder. Use the filter arrows on row 4.
A4: # | B4: Folder | C4: Subfolder | D4: Measure | E4: Description | F4: DAX formula | G4: Format string | H4: Data type | I4: Source tables | J4: Depends on | K4: Reference value (Year = 2025) | L4: Script file
A5: 1 | B5: 00 Utilities | D5: Data Through Date | E5: Latest order date in the data, ignoring all filters. | F5: CALCULATE(MAX(Orders[order_date]), REMOVEFILTERS()) | G5: dd-mmm-yyyy | H5: Date | I5: Orders | L5: NEXORA_Measures_Core.tmdl.txt
A6: 2 | B6: 00 Utilities | D6: Data Through Label | E6: Footer text for the report. | F6: "Data through " & FORMAT([Data Through Date], "dd mmm yyyy") | G6: (text) | H6: Text | J6: Data Through Date | L6: NEXORA_Measures_Core.tmdl.txt
A7: 3 | B7: 00 Utilities | D7: Selected Year | E7: Shows the selected year or All Years. | F7: IF(HASONEVALUE('Calendar'[Year]), FORMAT(SELECTEDVALUE('Calendar'[Year]), "0"), "All Years") | G7: (text) | H7: Text | I7: Calendar | L7: NEXORA_Measures_Core.tmdl.txt
A8: 4 | B8: 00 Utilities | D8: Period Label | E8: Subtitle describing the selected period. | F8: IF(HASONEVALUE('Calendar'[Year]), "Year " & FORMAT(SELECTEDVALUE('Calendar'[Year]), "0"), FORMAT(MIN('Calendar'[Date]), "MMM yyyy") & " – " & FORMAT(MAX('Calendar'[Date]), "MMM yyyy")) | G8: (text) | H8: Text | I8: Calendar | L8: NEXORA_Measures_Core.tmdl.txt
A9: 5 | B9: 00 Utilities | D9: Active Days | E9: Number of days with at least one valid order. | F9: CALCULATE( DISTINCTCOUNT(Orders[order_date]), Orders[order_status] <> "Cancelled", Orders[delivery_status] <> "Cancelled" ) | G9: #,0 | H9: Whole number | I9: Orders | L9: NEXORA_Measures_Core.tmdl.txt
A10: 6 | B10: 01 Sales & Profit | C10: Basket & Averages | D10: AOV | E10: Average order value. | F10: DIVIDE([Net Sales], [Total Orders]) | G10: \$#,0.00 | H10: Currency | J10: Net Sales, Total Orders | K10: 463.52 | L10: NEXORA_Measures_Core.tmdl.txt
A11: 7 | B11: 01 Sales & Profit | C11: Basket & Averages | D11: Units per Order | E11: Average number of units in a valid order. | F11: DIVIDE([Units Sold], [Total Orders]) | G11: 0.00 | H11: Decimal | J11: Units Sold, Total Orders | L11: NEXORA_Measures_Core.tmdl.txt
A12: 8 | B12: 01 Sales & Profit | C12: Basket & Averages | D12: Profit per Order | E12: Average profit earned per valid order. | F12: DIVIDE([Total Profit], [Total Orders]) | G12: \$#,0.00 | H12: Currency | J12: Total Profit, Total Orders | L12: NEXORA_Measures_Core.tmdl.txt
A13: 9 | B13: 01 Sales & Profit | C13: Basket & Averages | D13: Avg Selling Price | E13: Average gross selling price per unit sold. | F13: DIVIDE([Gross Sales], [Units Sold]) | G13: \$#,0.00 | H13: Currency | J13: Gross Sales, Units Sold | L13: NEXORA_Measures_Core.tmdl.txt
A14: 10 | B14: 01 Sales & Profit | C14: Basket & Averages | D14: Profit per Unit | E14: Average profit earned per unit sold. | F14: DIVIDE([Total Profit], [Units Sold]) | G14: \$#,0.00 | H14: Currency | J14: Total Profit, Units Sold | L14: NEXORA_Measures_Core.tmdl.txt
A15: 11 | B15: 01 Sales & Profit | C15: Core KPIs | D15: Gross Sales | E15: Quantity x unit price before discounts, tax and shipping. Cancelled orders excluded. | F15: CALCULATE( SUM(OrderItems[gross_sales]), Orders[order_status] <> "Cancelled", Orders[delivery_status] <> "Cancelled" ) | G15: \$#,0 | H15: Currency | I15: OrderItems, Orders | L15: NEXORA_Measures_Core.tmdl.txt
A16: 12 | B16: 01 Sales & Profit | C16: Core KPIs | D16: Discount | E16: Total discount value given. | F16: CALCULATE( SUM(OrderItems[discount_amount]), Orders[order_status] <> "Cancelled", Orders[delivery_status] <> "Cancelled" ) | G16: \$#,0 | H16: Currency | I16: OrderItems, Orders | L16: NEXORA_Measures_Core.tmdl.txt
A17: 13 | B17: 01 Sales & Profit | C17: Core KPIs | D17: Tax | E17: Tax charged on valid orders. | F17: CALCULATE( SUM(OrderItems[tax_amount]), Orders[order_status] <> "Cancelled", Orders[delivery_status] <> "Cancelled" ) | G17: \$#,0 | H17: Currency | I17: OrderItems, Orders | L17: NEXORA_Measures_Core.tmdl.txt
A18: 14 | B18: 01 Sales & Profit | C18: Core KPIs | D18: Shipping Cost | E18: Shipping cost charged on valid orders. | F18: CALCULATE( SUM(OrderItems[shipping_cost]), Orders[order_status] <> "Cancelled", Orders[delivery_status] <> "Cancelled" ) | G18: \$#,0 | H18: Currency | I18: OrderItems, Orders | L18: NEXORA_Measures_Core.tmdl.txt
A19: 15 | B19: 01 Sales & Profit | C19: Core KPIs | D19: Net Sales | E19: Gross - discount + tax + shipping (dataset definition). Cancelled orders excluded. | F19: CALCULATE( SUM(OrderItems[net_sales]), Orders[order_status] <> "Cancelled", Orders[delivery_status] <> "Cancelled" ) | G19: \$#,0 | H19: Currency | I19: OrderItems, Orders | K19: 5654533 | L19: NEXORA_Measures_Core.tmdl.txt
A20: 16 | B20: 01 Sales & Profit | C20: Core KPIs | D20: Product Cost | E20: Cost of the goods sold on valid orders. | F20: CALCULATE( SUM(OrderItems[product_cost]), Orders[order_status] <> "Cancelled", Orders[delivery_status] <> "Cancelled" ) | G20: \$#,0 | H20: Currency | I20: OrderItems, Orders | L20: NEXORA_Measures_Core.tmdl.txt
A21: 17 | B21: 01 Sales & Profit | C21: Core KPIs | D21: Total Profit | E21: Net sales - product cost - shipping cost (dataset definition). | F21: CALCULATE( SUM(OrderItems[profit]), Orders[order_status] <> "Cancelled", Orders[delivery_status] <> "Cancelled" ) | G21: \$#,0 | H21: Currency | I21: OrderItems, Orders | K21: 1910697 | L21: NEXORA_Measures_Core.tmdl.txt
A22: 18 | B22: 01 Sales & Profit | C22: Core KPIs | D22: Units Sold | E22: Total quantity sold on valid orders. | F22: CALCULATE( SUM(OrderItems[quantity]), Orders[order_status] <> "Cancelled", Orders[delivery_status] <> "Cancelled" ) | G22: #,0 | H22: Whole number | I22: OrderItems, Orders | K22: 54436 | L22: NEXORA_Measures_Core.tmdl.txt
A23: 19 | B23: 01 Sales & Profit | C23: Core KPIs | D23: Total Orders | E23: Distinct valid orders (cancelled excluded). | F23: CALCULATE( DISTINCTCOUNT(OrderItems[order_id]), Orders[order_status] <> "Cancelled", Orders[delivery_status] <> "Cancelled" ) | G23: #,0 | H23: Whole number | I23: OrderItems, Orders | K23: 12199 | L23: NEXORA_Measures_Core.tmdl.txt
A24: 20 | B24: 01 Sales & Profit | C24: Core KPIs | D24: Order Lines | E24: Number of order line items. | F24: CALCULATE( COUNTROWS(OrderItems), Orders[order_status] <> "Cancelled", Orders[delivery_status] <> "Cancelled" ) | G24: #,0 | H24: Whole number | I24: Orders | L24: NEXORA_Measures_Core.tmdl.txt
A25: 21 | B25: 01 Sales & Profit | C25: Core KPIs | D25: Net Revenue | E25: Gross sales minus discounts (excludes tax and shipping). | F25: [Gross Sales] - [Discount] | G25: \$#,0 | H25: Currency | J25: Gross Sales, Discount | L25: NEXORA_Measures_Core.tmdl.txt
A26: 22 | B26: 01 Sales & Profit | C26: Core KPIs | D26: Merchandise Profit | E26: Product profit before tax and shipping effects. | F26: [Net Revenue] - [Product Cost] | G26: \$#,0 | H26: Currency | J26: Net Revenue, Product Cost | L26: NEXORA_Measures_Core.tmdl.txt
A27: 23 | B27: 01 Sales & Profit | C27: Core KPIs | D27: Profit Margin % | E27: Total profit / net sales (same definition as the dataset). | F27: DIVIDE([Total Profit], [Net Sales]) | G27: 0.0% | H27: Percentage | J27: Total Profit, Net Sales | K27: 0.3379 | L27: NEXORA_Measures_Core.tmdl.txt
A28: 24 | B28: 01 Sales & Profit | C28: Core KPIs | D28: Merchandise Margin % | E28: Product margin on net revenue, before tax and shipping. | F28: DIVIDE([Merchandise Profit], [Net Revenue]) | G28: 0.0% | H28: Percentage | J28: Merchandise Profit, Net Revenue | K28: 0.258 | L28: NEXORA_Measures_Core.tmdl.txt
A29: 25 | B29: 01 Sales & Profit | C29: Discounts | D29: Discount % | E29: Discount value as % of gross sales. | F29: DIVIDE([Discount], [Gross Sales]) | G29: 0.0% | H29: Percentage | J29: Discount, Gross Sales | K29: 0.15 | L29: NEXORA_Measures_Core.tmdl.txt
A30: 26 | B30: 01 Sales & Profit | C30: Discounts | D30: Avg Line Discount % | E30: Simple average of the discount percentage across order lines. | F30: CALCULATE( AVERAGE(OrderItems[discount_percentage]), Orders[order_status] <> "Cancelled", Orders[delivery_status] <> "Cancelled" ) | G30: 0.0% | H30: Percentage | I30: OrderItems, Orders | L30: NEXORA_Measures_Core.tmdl.txt
A31: 27 | B31: 01 Sales & Profit | C31: Discounts | D31: High Discount Sales Share % | E31: Share of net sales on lines discounted 30% or more. | F31: DIVIDE(CALCULATE([Net Sales], OrderItems[discount_percentage] >= 0.3), [Net Sales]) | G31: 0.0% | H31: Percentage | I31: OrderItems | J31: Net Sales | K31: 0.075 | L31: NEXORA_Measures_Core.tmdl.txt
A32: 28 | B32: 01 Sales & Profit | C32: Discounts | D32: Margin % (Discount >= 30%) | E32: Profit margin on lines discounted 30% or more. | F32: DIVIDE(CALCULATE([Total Profit], OrderItems[discount_percentage] >= 0.3), CALCULATE([Net Sales], OrderItems[discount_percentage] >= 0.3)) | G32: 0.0% | H32: Percentage | I32: OrderItems | J32: Total Profit, Net Sales | K32: 0.116 | L32: NEXORA_Measures_Core.tmdl.txt
A33: 29 | B33: 01 Sales & Profit | C33: Discounts | D33: Margin % (Discount < 10%) | E33: Profit margin on lines discounted less than 10%. | F33: DIVIDE(CALCULATE([Total Profit], OrderItems[discount_percentage] < 0.1), CALCULATE([Net Sales], OrderItems[discount_percentage] < 0.1)) | G33: 0.0% | H33: Percentage | I33: OrderItems | J33: Total Profit, Net Sales | K33: 0.425 | L33: NEXORA_Measures_Core.tmdl.txt
A34: 30 | B34: 01 Sales & Profit | C34: Discounts | D34: Margin Erosion from Discounts (pts) | E34: Margin points lost on heavily discounted lines. | F34: [Margin % (Discount < 10%)] - [Margin % (Discount >= 30%)] | G34: 0.0% | H34: Percentage | J34: Margin % (Discount < 10%), Margin % (Discount >= 30%) | L34: NEXORA_Measures_Core.tmdl.txt
A35: 31 | B35: 01 Sales & Profit | C35: Order Status | D35: Net Sales (All Orders) | E35: Net sales including cancelled orders. | F35: SUM(OrderItems[net_sales]) | G35: \$#,0 | H35: Currency | I35: OrderItems | L35: NEXORA_Measures_Core.tmdl.txt
A36: 32 | B36: 01 Sales & Profit | C36: Order Status | D36: Orders (All Status) | E36: All orders including cancelled. | F36: DISTINCTCOUNT(OrderItems[order_id]) | G36: #,0 | H36: Whole number | I36: OrderItems | L36: NEXORA_Measures_Core.tmdl.txt
A37: 33 | B37: 01 Sales & Profit | C37: Order Status | D37: Cancelled Orders | E37: Orders lost to cancellation: all orders minus valid orders. | F37: [Orders (All Status)] - [Total Orders] | G37: #,0 | H37: Whole number | J37: Orders (All Status), Total Orders | L37: NEXORA_Measures_Core.tmdl.txt
A38: 34 | B38: 01 Sales & Profit | C38: Order Status | D38: Cancelled Sales | E38: Net sales value of cancelled orders: all-orders net sales minus valid net sales. | F38: [Net Sales (All Orders)] - [Net Sales] | G38: \$#,0 | H38: Currency | J38: Net Sales (All Orders), Net Sales | L38: NEXORA_Measures_Core.tmdl.txt
A39: 35 | B39: 01 Sales & Profit | C39: Order Status | D39: Cancellation Rate % | E39: Cancelled orders as a share of all orders. | F39: DIVIDE([Cancelled Orders], [Orders (All Status)]) | G39: 0.0% | H39: Percentage | J39: Cancelled Orders, Orders (All Status) | L39: NEXORA_Measures_Core.tmdl.txt
A40: 36 | B40: 01 Sales & Profit | C40: Order Status | D40: Completed Orders | E40: Orders whose status is Completed. | F40: CALCULATE(DISTINCTCOUNT(Orders[order_id]), Orders[order_status] = "Completed") | G40: #,0 | H40: Whole number | I40: Orders | L40: NEXORA_Measures_Core.tmdl.txt
A41: 37 | B41: 01 Sales & Profit | C41: Order Status | D41: Pending Orders | E41: Orders whose status is Pending. | F41: CALCULATE(DISTINCTCOUNT(Orders[order_id]), Orders[order_status] = "Pending") | G41: #,0 | H41: Whole number | I41: Orders | L41: NEXORA_Measures_Core.tmdl.txt
...

Sheet Model & Rules
A1: Model, Relationships and Business Rules
A2: The conventions every measure relies on.
A4: 1) Tables
A5: Table | B5: Key columns | C5: Role | D5: Rows
A6: Calendar | B6: Date, Year, Month No, Month, Quarter, Day No, Day | C6: Date table. Mark as date table; sort Month by Month No and Day by Day No. | D6: 4 years (2022-2025)
A7: Customers | B7: customer_id, customer_segment, customer_country, region, customer_acquisition_cost | C7: Customer attributes (one row per customer). | D7: 14,000
A8: Orders | B8: order_id, order_date, order_status, customer_id, delivery_status, return_status, customer_rating | C8: Order header: dates, status, delivery, returns, ratings, marketing, loyalty. | D8: 35,087
A9: OrderItems | B9: order_id, product_id, quantity, unit_price, discount_percentage, net_sales, profit | C9: Order lines: all money and quantity measures read this table. | D9: 89,105
A10: ProductCatalog | B10: product_id, product_name, product_category, product_subcategory, brand, supplier | C10: Product attributes. | D10: 1,250
A11: ALL Measures | B11: (measures only) | C11: Holds every measure. | D11: -
A13: 2) Relationships (all one-to-many, single direction)
A14: From (one side) | B14: To (many side) | C14: Purpose
A15: Calendar[Date] | B15: Orders[order_date] | C15: Time intelligence and the Year slicer.
A16: Customers[customer_id] | B16: Orders[customer_id] | C16: Customer attributes (country, segment, region).
A17: Orders[order_id] | B17: OrderItems[order_id] | C17: Links order attributes (status, channel) to order lines.
A18: ProductCatalog[product_id] | B18: OrderItems[product_id] | C18: Category, brand and product analysis.
A20: 3) Business rules
A21: Rule | B21: Definition
A22: Valid orders | B22: An order counts as a sale unless order_status or delivery_status is Cancelled. Pending and Returned orders stay in sales.
A23: Net Sales | B23: Gross sales - discount + tax + shipping (the dataset's own definition).
A24: Total Profit | B24: Net sales - product cost - shipping cost (the dataset's own definition).
A25: Profit Margin % | B25: Total profit / net sales.
A26: Merchandise Margin % | B26: (Gross sales - discount - product cost) / (gross sales - discount): product margin before tax and shipping.
A27: Money source | B27: Every money and quantity measure reads OrderItems; the Orders table supplies dates, status, delivery, returns, ratings, marketing and loyalty.
A28: Orders-level measures | B28: Delivery, returns, ratings and loyalty measures read the Orders table and are not filtered by the valid-order rule. Do not slice them by product fields.
A29: Time intelligence | B29: Calendar must be marked as a date table. Keep the Year slicer on a single year (2025) so YoY measures compare year against year.
A30: Currency | B30: All amounts are in USD (the currency column is a label).
A31: Same-column rule | B31: A measure that filters a column must not be used with that same column on a visual axis. Use KEEPFILTERS (see Reviewed Orders).
A33: 4) Calculated columns used by the visuals
A34: Column | B34: DAX | C34: Purpose | D34: Status
A35: Calendar[Year Month] | B35: FORMAT('Calendar'[Date], "MMM yyyy") | C35: Month-by-month axis; sort by Year Month No. | D35: Recommended
A36: Calendar[Year Month No] | B36: YEAR('Calendar'[Date]) * 100 + MONTH('Calendar'[Date]) | C36: Sort key for Year Month. | D36: Recommended
A37: OrderItems[Discount Band] | B37: SWITCH(TRUE(), OrderItems[discount_percentage] = 0, "0% (none)", OrderItems[discount_percentage] < 0.10, "1-9%", OrderItems[discount_percentage] < 0.20, "10-19%", OrderItems[discount_percentage] < 0.30, "20-29%", "30%+") | C37: Axis of the Discount Impact chart. | D37: Used on Products page
A38: OrderItems[Discount Band No] | B38: SWITCH(TRUE(), discount_percentage = 0, 1, < 0.10, 2, < 0.20, 3, < 0.30, 4, 5) | C38: Sort key for Discount Band. | D38: Used on Products page
A39: Customers[Acquisition Channel] | B39: Marketing channel of the customer's first order | C39: CAC and LTV by acquisition channel. | D39: Optional (advanced)
A40: Customers[Cohort Year] | B40: Year of the customer's first valid order | C40: Cohort retention matrix. | D40: Optional (advanced)
